# try...catch

In JavaScript, the `try...catch` statement is used to handle exceptions, providing a way to test for errors in a block of code and manage those errors if they occur. Here’s a detailed explanation of how it works:

### Structure and Syntax

#### `try`

The `try` block contains code that might throw an error. This code is executed normally until an error is encountered.

#### `catch`

The `catch` block contains code that runs if an error occurs in the `try` block. It is used to handle the error.

#### `finally`

The `finally` block is optional and contains code that will run after the `try` and `catch` blocks, regardless of whether an error was thrown or caught. This is useful for cleanup code that should always run.

#### Syntax

```javascript
try {
    // Code that may throw an error
} catch (error) {
    // Code to handle the error
} finally {
    // Code that will always execute (optional)
}
```

### Example

Here’s an example of using `try...catch` in JavaScript:

```javascript
function riskyFunction() {
    // This function might throw an error
    let randomNumber = Math.random();
    if (randomNumber < 0.5) {
        throw new Error("Random number is too low!");
    }
    return randomNumber;
}

try {
    let result = riskyFunction();
    console.log("Function executed successfully, result:", result);
} catch (error) {
    console.error("An error occurred:", error.message);
} finally {
    console.log("This will run regardless of whether an error occurred.");
}
```

### Explanation

1. **`try` Block**:

    - `riskyFunction()` is called within the `try` block.
    - If `riskyFunction()` executes without errors (i.e., `randomNumber >= 0.5`), the result is logged to the console.

2. **`catch` Block**:

    - If `riskyFunction()` throws an error (i.e., `randomNumber < 0.5`), the `catch` block executes.
    - The `error` object is automatically passed to the `catch` block, allowing access to the error message and other properties.
    - The error message is logged to the console.

3. **`finally` Block**:
    - The `finally` block executes after the `try` and `catch` blocks, regardless of whether an error was thrown or caught.
    - This is useful for cleanup tasks, such as closing resources or logging messages, that need to run no matter what.

### Advanced Usage

#### Nested `try...catch` Blocks

You can nest `try...catch` blocks to handle errors at different levels of your code:

```javascript
try {
    try {
        let result = riskyFunction();
        console.log(
            "Inner try: Function executed successfully, result:",
            result
        );
    } catch (innerError) {
        console.error("Inner catch: An error occurred:", innerError.message);
        throw new Error("Error in inner try block");
    }
} catch (outerError) {
    console.error("Outer catch: An error occurred:", outerError.message);
}
```

#### Catching Specific Errors

While JavaScript doesn’t allow specifying different `catch` blocks for different types of errors, you can differentiate errors within a single `catch` block by examining the error object:

```javascript
try {
    riskyFunction();
} catch (error) {
    if (error instanceof TypeError) {
        console.error("TypeError:", error.message);
    } else if (error instanceof RangeError) {
        console.error("RangeError:", error.message);
    } else {
        console.error("General error:", error.message);
    }
}
```

Using `try...catch` allows you to handle errors gracefully, ensuring your program can manage unexpected situations without crashing.
